Workbook

Sheet Dashboard
A1: RESTAURANT SALES DASHBOARD
A3: Total Revenue | C3: Total Orders | E3: Average Order Value | G3: Total Items Sold
A4: =Order_Analysis!B4 -> 159217.9 | C4: =Order_Analysis!B2 -> 5370 | E4: =Order_Analysis!B5 -> 29.649516 | G4: =Order_Analysis!B3 -> 12234
A44: KEY BUSINESS INSIGHTS | J44: TOP 5 HIGHEST-VALUE ORDERS
A45: • Korean Beef Bowl generated the highest revenue among individual menu items. | K45: Order ID | L45: Items | M45: Revenue
K46: 440 | L46: 14 | M46: 192.15
A47: • Hamburger was the most-ordered item by volume, highlighting the difference between sales volume and revenue contribution. | K47: 2075 | L47: 13 | M47: 191.05
K48: 1957 | L48: 14 | M48: 190.1
A49: • Order activity was concentrated during lunch and evening periods, indicating the busiest operating windows. | K49: 330 | L49: 14 | M49: 189.7
K50: 2675 | L50: 14 | M50: 185.1
A51: • The highest-value order was ₹192.15 and contained 14 items.
H57: Data Source: Maven Analytics — Restaurant Orders | Analysis Period: January 1, 2023 – March 31, 2023

Sheet Summary
A1: Menu_rows | B1: Order_Details_Rows | C1: Unique_Menu_Items | D1: Unique_orders | E1: Unique_Categories | F1: Earliest_Order_Date | G1: Latest_Order_Date
A2: =ROWS(Raw_Menu!A2:D33) -> 32 | B2: =ROWS(Raw_Orders!A2:A12235) -> 12234 | C2: =SUMPRODUCT((Raw_Menu!A2:A33<>"")/COUNTIF(Raw_Menu!A2:A33,Raw_Menu!A2:A33&"")) -> 32 | D2: =SUMPRODUCT((Raw_Orders!B2:B12235<>"")/COUNTIF(Raw_Orders!B2:B12235,Raw_Orders!B2:B12235&"")) -> 5370 | E2: =SUMPRODUCT((Raw_Menu!C2:C33<>"")/COUNTIF(Raw_Menu!C2:C33,Raw_Menu!C2:C33&"")) -> 4 | F2: 44927 | G2: 45016
A4: DATA QUALITY CHECK
A5: Blank_Cells_In_Menu | B5: =COUNTBLANK(Raw_Menu!A2:D33) -> 0
A6: Blank_Cells_In_Orders | B6: =COUNTBLANK(Raw_Orders!A2:A12235) -> 0
A7: Duplicate_Menu_IDs | B7: =SUMPRODUCT(--(COUNTIF(Raw_Menu!A2:A33,Raw_Menu!A2:A33)>1)) -> 0
A8: Duplicate_Order_Details_IDs | B8: =SUMPRODUCT(--(COUNTIF(Raw_Orders!A2:A12235,Raw_Orders!A2:A12235)>1)) -> 0
A9: Missing_Item_IDs_(NULL) | B9: =COUNTIF(Raw_Orders!E2:E12235,"NULL") -> 137

Sheet Menu_Analysis
A1: Category | B1: Items Sold | C1: Revenue
A2: American | B2: =COUNTIF(tblOrders[Category],A2) -> 2734 | C2: =SUMIF(tblOrders[Category],Menu_Analysis!A2,tblOrders[Revenue]) -> 28237.75
A3: Asian | B3: =COUNTIF(tblOrders[Category],A3) -> 3470 | C3: =SUMIF(tblOrders[Category],Menu_Analysis!A3,tblOrders[Revenue]) -> 46720.65
A4: Italian | B4: =COUNTIF(tblOrders[Category],A4) -> 2948 | C4: =SUMIF(tblOrders[Category],Menu_Analysis!A4,tblOrders[Revenue]) -> 49462.7
A5: Mexican | B5: =COUNTIF(tblOrders[Category],A5) -> 2945 | C5: =SUMIF(tblOrders[Category],Menu_Analysis!A5,tblOrders[Revenue]) -> 34796.8
A7: Item Name | B7: Category | C7: Items Sold | D7: Revenue
A8: =Raw_Menu!B10 -> Korean Beef Bowl | B8: =Raw_Menu!C10 -> Asian | C8: =COUNTIF(Raw_Orders!$E$2:$E$12235,Raw_Menu!A10) -> 588 | D8: =SUMIF(Raw_Orders!$E$2:$E$12235,Raw_Menu!A10,Raw_Orders!$G$2:$G$12235) -> 10554.6
A9: =Raw_Menu!B26 -> Spaghetti & Meatballs | B9: =Raw_Menu!C26 -> Italian | C9: =COUNTIF(Raw_Orders!$E$2:$E$12235,Raw_Menu!A26) -> 470 | D9: =SUMIF(Raw_Orders!$E$2:$E$12235,Raw_Menu!A26,Raw_Orders!$G$2:$G$12235) -> 8436.5
A10: =Raw_Menu!B9 -> Tofu Pad Thai | B10: =Raw_Menu!C9 -> Asian | C10: =COUNTIF(Raw_Orders!$E$2:$E$12235,Raw_Menu!A9) -> 562 | D10: =SUMIF(Raw_Orders!$E$2:$E$12235,Raw_Menu!A9,Raw_Orders!$G$2:$G$12235) -> 8149
A11: =Raw_Menu!B3 -> Cheeseburger | B11: =Raw_Menu!C3 -> American | C11: =COUNTIF(Raw_Orders!$E$2:$E$12235,Raw_Menu!A3) -> 583 | D11: =SUMIF(Raw_Orders!$E$2:$E$12235,Raw_Menu!A3,Raw_Orders!$G$2:$G$12235) -> 8132.85
A12: =Raw_Menu!B2 -> Hamburger | B12: =Raw_Menu!C2 -> American | C12: =COUNTIF(Raw_Orders!$E$2:$E$12235,Raw_Menu!A2) -> 622 | D12: =SUMIF(Raw_Orders!$E$2:$E$12235,Raw_Menu!A2,Raw_Orders!$G$2:$G$12235) -> 8054.9
A13: =Raw_Menu!B8 -> Orange Chicken | B13: =Raw_Menu!C8 -> Asian | C13: =COUNTIF(Raw_Orders!$E$2:$E$12235,Raw_Menu!A8) -> 456 | D13: =SUMIF(Raw_Orders!$E$2:$E$12235,Raw_Menu!A8,Raw_Orders!$G$2:$G$12235) -> 7524
A14: =Raw_Menu!B33 -> Eggplant Parmesan | B14: =Raw_Menu!C33 -> Italian | C14: =COUNTIF(Raw_Orders!$E$2:$E$12235,Raw_Menu!A33) -> 420 | D14: =SUMIF(Raw_Orders!$E$2:$E$12235,Raw_Menu!A33,Raw_Orders!$G$2:$G$12235) -> 7119
A15: =Raw_Menu!B21 -> Steak Torta | B15: =Raw_Menu!C21 -> Mexican | C15: =COUNTIF(Raw_Orders!$E$2:$E$12235,Raw_Menu!A21) -> 489 | D15: =SUMIF(Raw_Orders!$E$2:$E$12235,Raw_Menu!A21,Raw_Orders!$G$2:$G$12235) -> 6821.55
A16: =Raw_Menu!B32 -> Chicken Parmesan | B16: =Raw_Menu!C32 -> Italian | C16: =COUNTIF(Raw_Orders!$E$2:$E$12235,Raw_Menu!A32) -> 364 | D16: =SUMIF(Raw_Orders!$E$2:$E$12235,Raw_Menu!A32,Raw_Orders!$G$2:$G$12235) -> 6533.8
A17: =Raw_Menu!B11 -> Pork Ramen | B17: =Raw_Menu!C11 -> Asian | C17: =COUNTIF(Raw_Orders!$E$2:$E$12235,Raw_Menu!A11) -> 360 | D17: =SUMIF(Raw_Orders!$E$2:$E$12235,Raw_Menu!A11,Raw_Orders!$G$2:$G$12235) -> 6462
A18: =Raw_Menu!B18 -> Chicken Burrito | B18: =Raw_Menu!C18 -> Mexican | C18: =COUNTIF(Raw_Orders!$E$2:$E$12235,Raw_Menu!A18) -> 455 | D18: =SUMIF(Raw_Orders!$E$2:$E$12235,Raw_Menu!A18,Raw_Orders!$G$2:$G$12235) -> 5892.25
A19: =Raw_Menu!B30 -> Mushroom Ravioli | B19: =Raw_Menu!C30 -> Italian | C19: =COUNTIF(Raw_Orders!$E$2:$E$12235,Raw_Menu!A30) -> 359 | D19: =SUMIF(Raw_Orders!$E$2:$E$12235,Raw_Menu!A30,Raw_Orders!$G$2:$G$12235) -> 5564.5
A20: =Raw_Menu!B25 -> Spaghetti | B20: =Raw_Menu!C25 -> Italian | C20: =COUNTIF(Raw_Orders!$E$2:$E$12235,Raw_Menu!A25) -> 367 | D20: =SUMIF(Raw_Orders!$E$2:$E$12235,Raw_Menu!A25,Raw_Orders!$G$2:$G$12235) -> 5321.5
A21: =Raw_Menu!B19 -> Steak Burrito | B21: =Raw_Menu!C19 -> Mexican | C21: =COUNTIF(Raw_Orders!$E$2:$E$12235,Raw_Menu!A19) -> 354 | D21: =SUMIF(Raw_Orders!$E$2:$E$12235,Raw_Menu!A19,Raw_Orders!$G$2:$G$12235) -> 5292.3
A22: =Raw_Menu!B28 -> Meat Lasagna | B22: =Raw_Menu!C28 -> Italian | C22: =COUNTIF(Raw_Orders!$E$2:$E$12235,Raw_Menu!A28) -> 273 | D22: =SUMIF(Raw_Orders!$E$2:$E$12235,Raw_Menu!A28,Raw_Orders!$G$2:$G$12235) -> 4900.35
A23: =Raw_Menu!B13 -> Salmon Roll | B23: =Raw_Menu!C13 -> Asian | C23: =COUNTIF(Raw_Orders!$E$2:$E$12235,Raw_Menu!A13) -> 324 | D23: =SUMIF(Raw_Orders!$E$2:$E$12235,Raw_Menu!A13,Raw_Orders!$G$2:$G$12235) -> 4843.8
A24: =Raw_Menu!B31 -> Shrimp Scampi | B24: =Raw_Menu!C31 -> Italian | C24: =COUNTIF(Raw_Orders!$E$2:$E$12235,Raw_Menu!A31) -> 239 | D24: =SUMIF(Raw_Orders!$E$2:$E$12235,Raw_Menu!A31,Raw_Orders!$G$2:$G$12235) -> 4768.05
A25: =Raw_Menu!B20 -> Chicken Torta | B25: =Raw_Menu!C20 -> Mexican | C25: =COUNTIF(Raw_Orders!$E$2:$E$12235,Raw_Menu!A20) -> 379 | D25: =SUMIF(Raw_Orders!$E$2:$E$12235,Raw_Menu!A20,Raw_Orders!$G$2:$G$12235) -> 4529.05
A26: =Raw_Menu!B12 -> California Roll | B26: =Raw_Menu!C12 -> Asian | C26: =COUNTIF(Raw_Orders!$E$2:$E$12235,Raw_Menu!A12) -> 355 | D26: =SUMIF(Raw_Orders!$E$2:$E$12235,Raw_Menu!A12,Raw_Orders!$G$2:$G$12235) -> 4242.25
A27: =Raw_Menu!B7 -> French Fries | B27: =Raw_Menu!C7 -> American | C27: =COUNTIF(Raw_Orders!$E$2:$E$12235,Raw_Menu!A7) -> 571 | D27: =SUMIF(Raw_Orders!$E$2:$E$12235,Raw_Menu!A7,Raw_Orders!$G$2:$G$12235) -> 3997
A28: =Raw_Menu!B27 -> Fettuccine Alfredo | B28: =Raw_Menu!C27 -> Italian | C28: =COUNTIF(Raw_Orders!$E$2:$E$12235,Raw_Menu!A27) -> 249 | D28: =SUMIF(Raw_Orders!$E$2:$E$12235,Raw_Menu!A27,Raw_Orders!$G$2:$G$12235) -> 3610.5
A29: =Raw_Menu!B6 -> Mac & Cheese | B29: =Raw_Menu!C6 -> American | C29: =COUNTIF(Raw_Orders!$E$2:$E$12235,Raw_Menu!A6) -> 463 | D29: =SUMIF(Raw_Orders!$E$2:$E$12235,Raw_Menu!A6,Raw_Orders!$G$2:$G$12235) -> 3241
A30: =Raw_Menu!B23 -> Chips & Salsa | B30: =Raw_Menu!C23 -> Mexican | C30: =COUNTIF(Raw_Orders!$E$2:$E$12235,Raw_Menu!A23) -> 461 | D30: =SUMIF(Raw_Orders!$E$2:$E$12235,Raw_Menu!A23,Raw_Orders!$G$2:$G$12235) -> 3227
A31: =Raw_Menu!B29 -> Cheese Lasagna | B31: =Raw_Menu!C29 -> Italian | C31: =COUNTIF(Raw_Orders!$E$2:$E$12235,Raw_Menu!A29) -> 207 | D31: =SUMIF(Raw_Orders!$E$2:$E$12235,Raw_Menu!A29,Raw_Orders!$G$2:$G$12235) -> 3208.5
A32: =Raw_Menu!B14 -> Edamame | B32: =Raw_Menu!C14 -> Asian | C32: =COUNTIF(Raw_Orders!$E$2:$E$12235,Raw_Menu!A14) -> 620 | D32: =SUMIF(Raw_Orders!$E$2:$E$12235,Raw_Menu!A14,Raw_Orders!$G$2:$G$12235) -> 3100
A33: =Raw_Menu!B17 -> Steak Tacos | B33: =Raw_Menu!C17 -> Mexican | C33: =COUNTIF(Raw_Orders!$E$2:$E$12235,Raw_Menu!A17) -> 214 | D33: =SUMIF(Raw_Orders!$E$2:$E$12235,Raw_Menu!A17,Raw_Orders!$G$2:$G$12235) -> 2985.3
A34: =Raw_Menu!B5 -> Veggie Burger | B34: =Raw_Menu!C5 -> American | C34: =COUNTIF(Raw_Orders!$E$2:$E$12235,Raw_Menu!A5) -> 238 | D34: =SUMIF(Raw_Orders!$E$2:$E$12235,Raw_Menu!A5,Raw_Orders!$G$2:$G$12235) -> 2499
A35: =Raw_Menu!B22 -> Cheese Quesadillas | B35: =Raw_Menu!C22 -> Mexican | C35: =COUNTIF(Raw_Orders!$E$2:$E$12235,Raw_Menu!A22) -> 233 | D35: =SUMIF(Raw_Orders!$E$2:$E$12235,Raw_Menu!A22,Raw_Orders!$G$2:$G$12235) -> 2446.5
A36: =Raw_Menu!B4 -> Hot Dog | B36: =Raw_Menu!C4 -> American | C36: =COUNTIF(Raw_Orders!$E$2:$E$12235,Raw_Menu!A4) -> 257 | D36: =SUMIF(Raw_Orders!$E$2:$E$12235,Raw_Menu!A4,Raw_Orders!$G$2:$G$12235) -> 2313
A37: =Raw_Menu!B24 -> Chips & Guacamole | B37: =Raw_Menu!C24 -> Mexican | C37: =COUNTIF(Raw_Orders!$E$2:$E$12235,Raw_Menu!A24) -> 237 | D37: =SUMIF(Raw_Orders!$E$2:$E$12235,Raw_Menu!A24,Raw_Orders!$G$2:$G$12235) -> 2133
A38: =Raw_Menu!B15 -> Potstickers | B38: =Raw_Menu!C15 -> Asian | C38: =COUNTIF(Raw_Orders!$E$2:$E$12235,Raw_Menu!A15) -> 205 | D38: =SUMIF(Raw_Orders!$E$2:$E$12235,Raw_Menu!A15,Raw_Orders!$G$2:$G$12235) -> 1845
A39: =Raw_Menu!B16 -> Chicken Tacos | B39: =Raw_Menu!C16 -> Mexican | C39: =COUNTIF(Raw_Orders!$E$2:$E$12235,Raw_Menu!A16) -> 123 | D39: =SUMIF(Raw_Orders!$E$2:$E$12235,Raw_Menu!A16,Raw_Orders!$G$2:$G$12235) -> 1469.85

Sheet Order_Analysis
A1: KPI | B1: Value | G1: Count of total order Id | K1: ORDER ID | L1: ITEMS | M1: REVENUE
A2: Total Orders | B2: 5370 | G2: 1 | H2: 1 | I2: =COUNTIF(G2:G5371,H2) -> 2053
A3: Total Items Sold | B3: =COUNTA(Raw_Orders!A2:A12235) -> 12234 | G3: 5 | H3: 2 | I3: =COUNTIF(G3:G5372,H3) -> 1559
A4: Total Revenue | B4: =SUM(Raw_Orders!G2:G12235) -> 159217.9 | G4: 2 | H4: 3 | I4: =COUNTIF(G4:G5373,H4) -> 835
A5: Average Order Value | B5: =B4/B2 -> 29.649516 | G5: 1 | H5: 4 | I5: =COUNTIF(G5:G5374,H5) -> 734
A6: Average Items Per Order | B6: =B3/B2 -> 2.2782123 | G6: 1 | H6: 5 | I6: =COUNTIF(G6:G5375,H6) -> 38
A7: Highest Order Value | B7: =MAX(Pivot!C4:C5373) -> 192.15 | G7: 2 | H7: 6 | I7: =COUNTIF(G7:G5376,H7) -> 20
A8: Lowest Order Value | B8: =MIN(Pivot!C4:C5346) -> 0 | G8: 1 | H8: 7 | I8: =COUNTIF(G8:G5377,H8) -> 18
A9: Average Order Value | B9: =AVERAGE(Pivot!C4:C5373) -> 29.649516 | G9: 1 | H9: 8 | I9: =COUNTIF(G9:G5378,H9) -> 24
A10: Highest Items in One Order | B10: =MAX(Pivot!B4:B5373) -> 14 | G10: 9 | H10: 9 | I10: =COUNTIF(G10:G5379,H10) -> 18
A11: Hour | B11: Items Ordered | C11: Revenue | G11: 2 | H11: 10 | I11: =COUNTIF(G11:G5380,H11) -> 16
A12: 10 | B12: =COUNTIF(tblOrders[Order_Hour],Order_Analysis!A12) -> 5 | C12: =SUMIF(tblOrders[Order_Hour],Order_Analysis!A12,tblOrders[Revenue]) -> 63.35 | G12: 4 | H12: 11 | I12: =COUNTIF(G12:G5381,H12) -> 12
A13: 11 | B13: =COUNTIF(tblOrders[Order_Hour],Order_Analysis!A13) -> 630 | C13: =SUMIF(tblOrders[Order_Hour],Order_Analysis!A13,tblOrders[Revenue]) -> 8122.5 | G13: 4 | H13: 12 | I13: =COUNTIF(G13:G5382,H13) -> 19
A14: 12 | B14: =COUNTIF(tblOrders[Order_Hour],Order_Analysis!A14) -> 1672 | C14: =SUMIF(tblOrders[Order_Hour],Order_Analysis!A14,tblOrders[Revenue]) -> 21718.4 | E14: =SUM(B12:B25) -> 12234 | G14: 1 | H14: 13 | I14: =COUNTIF(G14:G5383,H14) -> 15
A15: 13 | B15: =COUNTIF(tblOrders[Order_Hour],Order_Analysis!A15) -> 1575 | C15: =SUMIF(tblOrders[Order_Hour],Order_Analysis!A15,tblOrders[Revenue]) -> 20640.25 | E15: =SUM(C12:C25) -> 159217.9 | G15: 1 | H15: 14 | I15: =COUNTIF(G15:G5384,H15) -> 8
A16: 14 | B16: =COUNTIF(tblOrders[Order_Hour],Order_Analysis!A16) -> 968 | C16: =SUMIF(tblOrders[Order_Hour],Order_Analysis!A16,tblOrders[Revenue]) -> 12615.7 | G16: 4 | H16: Total | I16: =SUM(I2:I15) -> 5369
A17: 15 | B17: =COUNTIF(tblOrders[Order_Hour],Order_Analysis!A17) -> 751 | C17: =SUMIF(tblOrders[Order_Hour],Order_Analysis!A17,tblOrders[Revenue]) -> 9803.9 | G17: 3
A18: 16 | B18: =COUNTIF(tblOrders[Order_Hour],Order_Analysis!A18) -> 1054 | C18: =SUMIF(tblOrders[Order_Hour],Order_Analysis!A18,tblOrders[Revenue]) -> 13711.65 | G18: 10
A19: 17 | B19: =COUNTIF(tblOrders[Order_Hour],Order_Analysis!A19) -> 1370 | C19: =SUMIF(tblOrders[Order_Hour],Order_Analysis!A19,tblOrders[Revenue]) -> 17869.5 | G19: 1
A20: 18 | B20: =COUNTIF(tblOrders[Order_Hour],Order_Analysis!A20) -> 1307 | C20: =SUMIF(tblOrders[Order_Hour],Order_Analysis!A20,tblOrders[Revenue]) -> 16861.5 | G20: 2
A21: 19 | B21: =COUNTIF(tblOrders[Order_Hour],Order_Analysis!A21) -> 1085 | C21: =SUMIF(tblOrders[Order_Hour],Order_Analysis!A21,tblOrders[Revenue]) -> 14172.6 | G21: 2
A22: 20 | B22: =COUNTIF(tblOrders[Order_Hour],Order_Analysis!A22) -> 889 | C22: =SUMIF(tblOrders[Order_Hour],Order_Analysis!A22,tblOrders[Revenue]) -> 11678.6 | G22: 1
A23: 21 | B23: =COUNTIF(tblOrders[Order_Hour],Order_Analysis!A23) -> 608 | C23: =SUMIF(tblOrders[Order_Hour],Order_Analysis!A23,tblOrders[Revenue]) -> 7754.35 | G23: 3
A24: 22 | B24: =COUNTIF(tblOrders[Order_Hour],Order_Analysis!A24) -> 309 | C24: =SUMIF(tblOrders[Order_Hour],Order_Analysis!A24,tblOrders[Revenue]) -> 4047.8 | G24: 1
A25: 23 | B25: =COUNTIF(tblOrders[Order_Hour],Order_Analysis!A25) -> 11 | C25: =SUMIF(tblOrders[Order_Hour],Order_Analysis!A25,tblOrders[Revenue]) -> 157.8 | G25: 4
G26: 2
G27: 2
G28: 3
G29: 1
G30: 1
G31: 1
G32: 2
G33: 4
G34: 2
G35: 1
G36: 4
G37: 2
... G5371: 1

Sheet Raw_Menu
A1: menu_item_id | B1: item_name | C1: category | D1: price
A2: 101 | B2: Hamburger | C2: American | D2: 12.95
A3: 102 | B3: Cheeseburger | C3: American | D3: 13.95
A4: 103 | B4: Hot Dog | C4: American | D4: 9
A5: 104 | B5: Veggie Burger | C5: American | D5: 10.5
A6: 105 | B6: Mac & Cheese | C6: American | D6: 7
A7: 106 | B7: French Fries | C7: American | D7: 7
A8: 107 | B8: Orange Chicken | C8: Asian | D8: 16.5
A9: 108 | B9: Tofu Pad Thai | C9: Asian | D9: 14.5
A10: 109 | B10: Korean Beef Bowl | C10: Asian | D10: 17.95
A11: 110 | B11: Pork Ramen | C11: Asian | D11: 17.95
A12: 111 | B12: California Roll | C12: Asian | D12: 11.95
A13: 112 | B13: Salmon Roll | C13: Asian | D13: 14.95
... A33: 132 | B33: Eggplant Parmesan | C33: Italian | D33: 16.95

Sheet Pivot
A3: Row Labels | B3: Count of order_details_id | C3: Sum of Revenue | E3: Row Labels | F3: Count of order_details_id
A4: 1 | B4: 1 | C4: 17.95 | E4: 1 | F4: 1
A5: 2 | B5: 5 | C5: 64.45 | E5: 2 | F5: 1
A6: 3 | B6: 2 | C6: 24.9 | E6: 3 | F6: 1
A7: 4 | B7: 1 | C7: 12.95 | E7: 4 | F7: 1
A8: 5 | B8: 1 | C8: 12.95 | E8: 5 | F8: 1
A9: 6 | B9: 2 | C9: 21.95 | E9: 6 | F9: 1
A10: 7 | B10: 1 | C10: 9 | E10: 7 | F10: 1
A11: 8 | B11: 1 | C11: 9 | E11: 8 | F11: 1
A12: 9 | B12: 9 | C12: 132.25 | E12: 9 | F12: 1
A13: 10 | B13: 2 | C13: 22.5 | E13: 10 | F13: 1
A14: 11 | B14: 4 | C14: 45.85 | E14: 11 | F14: 1
A15: 12 | B15: 4 | C15: 51.35 | E15: 12 | F15: 1
... A5373: 5370 | B5373: 1 | C5373: 7 | E5373: 5370 | F5373: 1
A5374: Grand Total | B5374: 12234 | C5374: 159217.9 | E5374: 5371 | F5374: 1
E5375: 5372 | F5375: 1
E5376: 5373 | F5376: 1
E5377: 5374 | F5377: 1
E5378: 5375 | F5378: 1
E5379: 5376 | F5379: 1
E5380: 5377 | F5380: 1
E5381: 5378 | F5381: 1
E5382: 5379 | F5382: 1
E5383: 5380 | F5383: 1
E5384: 5381 | F5384: 1
E5385: 5382 | F5385: 1
E5386: 5383 | F5386: 1
... E12237: 12234 | F12237: 1
E12238: Grand Total | F12238: 12234

Sheet Raw_Orders
A1: order_details_id | B1: order_id | C1: order_date | D1: order_time | E1: item_id | F1: Item_Price | G1: Revenue | H1: Order_Hour | I1: Category
A2: 1 | B2: 1 | C2: 44927 | D2: 0.48513889 | E2: 109 | F2: =IFERROR(VLOOKUP(E2,Raw_Menu!$A$2:$D$33,4,FALSE),0) -> 17.95 | G2: =VALUE(F2) -> 17.95 | H2: =HOUR(D2) -> 11 | I2: =IFERROR(VLOOKUP(tblOrders[[#This Row],[item_id]],Raw_Menu!$A$2:$D$33,3,FALSE),"Unknown") -> Asian
A3: 2 | B3: 2 | C3: 44927 | D3: 0.49837963 | E3: 108 | F3: =IFERROR(VLOOKUP(E3,Raw_Menu!$A$2:$D$33,4,FALSE),0) -> 14.5 | G3: =VALUE(F3) -> 14.5 | H3: =HOUR(D3) -> 11 | I3: =IFERROR(VLOOKUP(tblOrders[[#This Row],[item_id]],Raw_Menu!$A$2:$D$33,3,FALSE),"Unknown") -> Asian | K3: =COUNTBLANK(tblOrders[Order_Hour]) -> 0
A4: 3 | B4: 2 | C4: 44927 | D4: 0.49837963 | E4: 124 | F4: =IFERROR(VLOOKUP(E4,Raw_Menu!$A$2:$D$33,4,FALSE),0) -> 14.5 | G4: =VALUE(F4) -> 14.5 | H4: =HOUR(D4) -> 11 | I4: =IFERROR(VLOOKUP(tblOrders[[#This Row],[item_id]],Raw_Menu!$A$2:$D$33,3,FALSE),"Unknown") -> Italian
A5: 4 | B5: 2 | C5: 44927 | D5: 0.49837963 | E5: 117 | F5: =IFERROR(VLOOKUP(E5,Raw_Menu!$A$2:$D$33,4,FALSE),0) -> 12.95 | G5: =VALUE(F5) -> 12.95 | H5: =HOUR(D5) -> 11 | I5: =IFERROR(VLOOKUP(tblOrders[[#This Row],[item_id]],Raw_Menu!$A$2:$D$33,3,FALSE),"Unknown") -> Mexican
A6: 5 | B6: 2 | C6: 44927 | D6: 0.49837963 | E6: 129 | F6: =IFERROR(VLOOKUP(E6,Raw_Menu!$A$2:$D$33,4,FALSE),0) -> 15.5 | G6: =VALUE(F6) -> 15.5 | H6: =HOUR(D6) -> 11 | I6: =IFERROR(VLOOKUP(tblOrders[[#This Row],[item_id]],Raw_Menu!$A$2:$D$33,3,FALSE),"Unknown") -> Italian
A7: 6 | B7: 2 | C7: 44927 | D7: 0.49837963 | E7: 106 | F7: =IFERROR(VLOOKUP(E7,Raw_Menu!$A$2:$D$33,4,FALSE),0) -> 7 | G7: =VALUE(F7) -> 7 | H7: =HOUR(D7) -> 11 | I7: =IFERROR(VLOOKUP(tblOrders[[#This Row],[item_id]],Raw_Menu!$A$2:$D$33,3,FALSE),"Unknown") -> American
A8: 7 | B8: 3 | C8: 44927 | D8: 0.50865741 | E8: 117 | F8: =IFERROR(VLOOKUP(E8,Raw_Menu!$A$2:$D$33,4,FALSE),0) -> 12.95 | G8: =VALUE(F8) -> 12.95 | H8: =HOUR(D8) -> 12 | I8: =IFERROR(VLOOKUP(tblOrders[[#This Row],[item_id]],Raw_Menu!$A$2:$D$33,3,FALSE),"Unknown") -> Mexican
A9: 8 | B9: 3 | C9: 44927 | D9: 0.50865741 | E9: 119 | F9: =IFERROR(VLOOKUP(E9,Raw_Menu!$A$2:$D$33,4,FALSE),0) -> 11.95 | G9: =VALUE(F9) -> 11.95 | H9: =HOUR(D9) -> 12 | I9: =IFERROR(VLOOKUP(tblOrders[[#This Row],[item_id]],Raw_Menu!$A$2:$D$33,3,FALSE),"Unknown") -> Mexican
A10: 9 | B10: 4 | C10: 44927 | D10: 0.51146991 | E10: 117 | F10: =IFERROR(VLOOKUP(E10,Raw_Menu!$A$2:$D$33,4,FALSE),0) -> 12.95 | G10: =VALUE(F10) -> 12.95 | H10: =HOUR(D10) -> 12 | I10: =IFERROR(VLOOKUP(tblOrders[[#This Row],[item_id]],Raw_Menu!$A$2:$D$33,3,FALSE),"Unknown") -> Mexican
A11: 10 | B11: 5 | C11: 44927 | D11: 0.51493056 | E11: 117 | F11: =IFERROR(VLOOKUP(E11,Raw_Menu!$A$2:$D$33,4,FALSE),0) -> 12.95 | G11: =VALUE(F11) -> 12.95 | H11: =HOUR(D11) -> 12 | I11: =IFERROR(VLOOKUP(tblOrders[[#This Row],[item_id]],Raw_Menu!$A$2:$D$33,3,FALSE),"Unknown") -> Mexican
A12: 11 | B12: 6 | C12: 44927 | D12: 0.52055556 | E12: 101 | F12: =IFERROR(VLOOKUP(E12,Raw_Menu!$A$2:$D$33,4,FALSE),0) -> 12.95 | G12: =VALUE(F12) -> 12.95 | H12: =HOUR(D12) -> 12 | I12: =IFERROR(VLOOKUP(tblOrders[[#This Row],[item_id]],Raw_Menu!$A$2:$D$33,3,FALSE),"Unknown") -> American
A13: 12 | B13: 6 | C13: 44927 | D13: 0.52055556 | E13: 114 | F13: =IFERROR(VLOOKUP(E13,Raw_Menu!$A$2:$D$33,4,FALSE),0) -> 9 | G13: =VALUE(F13) -> 9 | H13: =HOUR(D13) -> 12 | I13: =IFERROR(VLOOKUP(tblOrders[[#This Row],[item_id]],Raw_Menu!$A$2:$D$33,3,FALSE),"Unknown") -> Asian
A14: 13 | B14: 7 | C14: 44927 | D14: 0.53515046 | E14: 123 | F14: =IFERROR(VLOOKUP(E14,Raw_Menu!$A$2:$D$33,4,FALSE),0) -> 9 | G14: =VALUE(F14) -> 9 | H14: =HOUR(D14) -> 12 | I14: =IFERROR(VLOOKUP(tblOrders[[#This Row],[item_id]],Raw_Menu!$A$2:$D$33,3,FALSE),"Unknown") -> Mexican
A15: 14 | B15: 8 | C15: 44927 | D15: 0.53584491 | E15: 123 | F15: =IFERROR(VLOOKUP(E15,Raw_Menu!$A$2:$D$33,4,FALSE),0) -> 9 | G15: =VALUE(F15) -> 9 | H15: =HOUR(D15) -> 12 | I15: =IFERROR(VLOOKUP(tblOrders[[#This Row],[item_id]],Raw_Menu!$A$2:$D$33,3,FALSE),"Unknown") -> Mexican
... A122: 121 | B122: 49 | C122: 44927 | D122: 0.77291667 | E122: 120 | F122: =IFERROR(VLOOKUP(E122,Raw_Menu!$A$2:$D$33,4,FALSE),0) -> 13.95 | G122: =VALUE(F122) -> 13.95 | H122: =HOUR(D122) -> 18 | I122: =IFERROR(VLOOKUP(tblOrders[[#This Row],[item_id]],Raw_Menu!$A$2:$D$33,3,FALSE),"Unknown") -> Mexican
A123: 122 | B123: 50 | C123: 44927 | D123: 0.7784838 | E123: NULL | F123: =IFERROR(VLOOKUP(E123,Raw_Menu!$A$2:$D$33,4,FALSE),0) -> 0 | G123: =VALUE(F123) -> 0 | H123: =HOUR(D123) -> 18 | I123: =IFERROR(VLOOKUP(tblOrders[[#This Row],[item_id]],Raw_Menu!$A$2:$D$33,3,FALSE),"Unknown") -> Unknown
A124: 123 | B124: 51 | C124: 44927 | D124: 0.78365741 | E124: 101 | F124: =IFERROR(VLOOKUP(E124,Raw_Menu!$A$2:$D$33,4,FALSE),0) -> 12.95 | G124: =VALUE(F124) -> 12.95 | H124: =HOUR(D124) -> 18 | I124: =IFERROR(VLOOKUP(tblOrders[[#This Row],[item_id]],Raw_Menu!$A$2:$D$33,3,FALSE),"Unknown") -> American
A125: 124 | B125: 51 | C125: 44927 | D125: 0.78365741 | E125: 112 | F125: =IFERROR(VLOOKUP(E125,Raw_Menu!$A$2:$D$33,4,FALSE),0) -> 14.95 | G125: =VALUE(F125) -> 14.95 | H125: =HOUR(D125) -> 18 | I125: =IFERROR(VLOOKUP(tblOrders[[#This Row],[item_id]],Raw_Menu!$A$2:$D$33,3,FALSE),"Unknown") -> Asian
A126: 125 | B126: 52 | C126: 44927 | D126: 0.7868287 | E126: 109 | F126: =IFERROR(VLOOKUP(E126,Raw_Menu!$A$2:$D$33,4,FALSE),0) -> 17.95 | G126: =VALUE(F126) -> 17.95 | H126: =HOUR(D126) -> 18 | I126: =IFERROR(VLOOKUP(tblOrders[[#This Row],[item_id]],Raw_Menu!$A$2:$D$33,3,FALSE),"Unknown") -> Asian
A127: 126 | B127: 52 | C127: 44927 | D127: 0.7868287 | E127: 129 | F127: =IFERROR(VLOOKUP(E127,Raw_Menu!$A$2:$D$33,4,FALSE),0) -> 15.5 | G127: =VALUE(F127) -> 15.5 | H127: =HOUR(D127) -> 18 | I127: =IFERROR(VLOOKUP(tblOrders[[#This Row],[item_id]],Raw_Menu!$A$2:$D$33,3,FALSE),"Unknown") -> Italian
A128: 127 | B128: 52 | C128: 44927 | D128: 0.7868287 | E128: 122 | F128: =IFERROR(VLOOKUP(E128,Raw_Menu!$A$2:$D$33,4,FALSE),0) -> 7 | G128: =VALUE(F128) -> 7 | H128: =HOUR(D128) -> 18 | I128: =IFERROR(VLOOKUP(tblOrders[[#This Row],[item_id]],Raw_Menu!$A$2:$D$33,3,FALSE),"Unknown") -> Mexican
A129: 128 | B129: 53 | C129: 44927 | D129: 0.78769676 | E129: 112 | F129: =IFERROR(VLOOKUP(E129,Raw_Menu!$A$2:$D$33,4,FALSE),0) -> 14.95 | G129: =VALUE(F129) -> 14.95 | H129: =HOUR(D129) -> 18 | I129: =IFERROR(VLOOKUP(tblOrders[[#This Row],[item_id]],Raw_Menu!$A$2:$D$33,3,FALSE),"Unknown") -> Asian
A130: 129 | B130: 53 | C130: 44927 | D130: 0.78769676 | E130: 123 | F130: =IFERROR(VLOOKUP(E130,Raw_Menu!$A$2:$D$33,4,FALSE),0) -> 9 | G130: =VALUE(F130) -> 9 | H130: =HOUR(D130) -> 18 | I130: =IFERROR(VLOOKUP(tblOrders[[#This Row],[item_id]],Raw_Menu!$A$2:$D$33,3,FALSE),"Unknown") -> Mexican
A131: 130 | B131: 54 | C131: 44927 | D131: 0.79288194 | E131: 119 | F131: =IFERROR(VLOOKUP(E131,Raw_Menu!$A$2:$D$33,4,FALSE),0) -> 11.95 | G131: =VALUE(F131) -> 11.95 | H131: =HOUR(D131) -> 19 | I131: =IFERROR(VLOOKUP(tblOrders[[#This Row],[item_id]],Raw_Menu!$A$2:$D$33,3,FALSE),"Unknown") -> Mexican
A132: 131 | B132: 54 | C132: 44927 | D132: 0.79288194 | E132: 106 | F132: =IFERROR(VLOOKUP(E132,Raw_Menu!$A$2:$D$33,4,FALSE),0) -> 7 | G132: =VALUE(F132) -> 7 | H132: =HOUR(D132) -> 19 | I132: =IFERROR(VLOOKUP(tblOrders[[#This Row],[item_id]],Raw_Menu!$A$2:$D$33,3,FALSE),"Unknown") -> American
A133: 132 | B133: 55 | C133: 44927 | D133: 0.79396991 | E133: 118 | F133: =IFERROR(VLOOKUP(E133,Raw_Menu!$A$2:$D$33,4,FALSE),0) -> 14.95 | G133: =VALUE(F133) -> 14.95 | H133: =HOUR(D133) -> 19 | I133: =IFERROR(VLOOKUP(tblOrders[[#This Row],[item_id]],Raw_Menu!$A$2:$D$33,3,FALSE),"Unknown") -> Mexican
A134: 133 | B134: 55 | C134: 44927 | D134: 0.79396991 | E134: 122 | F134: =IFERROR(VLOOKUP(E134,Raw_Menu!$A$2:$D$33,4,FALSE),0) -> 7 | G134: =VALUE(F134) -> 7 | H134: =HOUR(D134) -> 19 | I134: =IFERROR(VLOOKUP(tblOrders[[#This Row],[item_id]],Raw_Menu!$A$2:$D$33,3,FALSE),"Unknown") -> Mexican
A135: 134 | B135: 56 | C135: 44927 | D135: 0.79652778 | E135: 108 | F135: =IFERROR(VLOOKUP(E135,Raw_Menu!$A$2:$D$33,4,FALSE),0) -> 14.5 | G135: =VALUE(F135) -> 14.5 | H135: =HOUR(D135) -> 19 | I135: =IFERROR(VLOOKUP(tblOrders[[#This Row],[item_id]],Raw_Menu!$A$2:$D$33,3,FALSE),"Unknown") -> Asian
... A298: 297 | B298: 124 | C298: 44928 | D298: 0.84206019 | E298: 114 | F298: =IFERROR(VLOOKUP(E298,Raw_Menu!$A$2:$D$33,4,FALSE),0) -> 9 | G298: =VALUE(F298) -> 9 | H298: =HOUR(D298) -> 20 | I298: =IFERROR(VLOOKUP(tblOrders[[#This Row],[item_id]],Raw_Menu!$A$2:$D$33,3,FALSE),"Unknown") -> Asian
A299: 298 | B299: 125 | C299: 44928 | D299: 0.85493056 | E299: NULL | F299: =IFERROR(VLOOKUP(E299,Raw_Menu!$A$2:$D$33,4,FALSE),0) -> 0 | G299: =VALUE(F299) -> 0 | H299: =HOUR(D299) -> 20 | I299: =IFERROR(VLOOKUP(tblOrders[[#This Row],[item_id]],Raw_Menu!$A$2:$D$33,3,FALSE),"Unknown") -> Unknown
A300: 299 | B300: 126 | C300: 44928 | D300: 0.870625 | E300: 132 | F300: =IFERROR(VLOOKUP(E300,Raw_Menu!$A$2:$D$33,4,FALSE),0) -> 16.95 | G300: =VALUE(F300) -> 16.95 | H300: =HOUR(D300) -> 20 | I300: =IFERROR(VLOOKUP(tblOrders[[#This Row],[item_id]],Raw_Menu!$A$2:$D$33,3,FALSE),"Unknown") -> Italian
A301: 300 | B301: 127 | C301: 44928 | D301: 0.87387731 | E301: 113 | F301: =IFERROR(VLOOKUP(E301,Raw_Menu!$A$2:$D$33,4,FALSE),0) -> 5 | G301: =VALUE(F301) -> 5 | H301: =HOUR(D301) -> 20 | I301: =IFERROR(VLOOKUP(tblOrders[[#This Row],[item_id]],Raw_Menu!$A$2:$D$33,3,FALSE),"Unknown") -> Asian
A302: 301 | B302: 128 | C302: 44928 | D302: 0.87854167 | E302: 122 | F302: =IFERROR(VLOOKUP(E302,Raw_Menu!$A$2:$D$33,4,FALSE),0) -> 7 | G302: =VALUE(F302) -> 7 | H302: =HOUR(D302) -> 21 | I302: =IFERROR(VLOOKUP(tblOrders[[#This Row],[item_id]],Raw_Menu!$A$2:$D$33,3,FALSE),"Unknown") -> Mexican
A303: 302 | B303: 129 | C303: 44928 | D303: 0.88405093 | E303: 107 | F303: =IFERROR(VLOOKUP(E303,Raw_Menu!$A$2:$D$33,4,FALSE),0) -> 16.5 | G303: =VALUE(F303) -> 16.5 | H303: =HOUR(D303) -> 21 | I303: =IFERROR(VLOOKUP(tblOrders[[#This Row],[item_id]],Raw_Menu!$A$2:$D$33,3,FALSE),"Unknown") -> Asian
A304: 303 | B304: 129 | C304: 44928 | D304: 0.88405093 | E304: 114 | F304: =IFERROR(VLOOKUP(E304,Raw_Menu!$A$2:$D$33,4,FALSE),0) -> 9 | G304: =VALUE(F304) -> 9 | H304: =HOUR(D304) -> 21 | I304: =IFERROR(VLOOKUP(tblOrders[[#This Row],[item_id]],Raw_Menu!$A$2:$D$33,3,FALSE),"Unknown") -> Asian
A305: 304 | B305: 130 | C305: 44928 | D305: 0.8853588 | E305: 109 | F305: =IFERROR(VLOOKUP(E305,Raw_Menu!$A$2:$D$33,4,FALSE),0) -> 17.95 | G305: =VALUE(F305) -> 17.95 | H305: =HOUR(D305) -> 21 | I305: =IFERROR(VLOOKUP(tblOrders[[#This Row],[item_id]],Raw_Menu!$A$2:$D$33,3,FALSE),"Unknown") -> Asian
A306: 305 | B306: 130 | C306: 44928 | D306: 0.8853588 | E306: 110 | F306: =IFERROR(VLOOKUP(E306,Raw_Menu!$A$2:$D$33,4,FALSE),0) -> 17.95 | G306: =VALUE(F306) -> 17.95 | H306: =HOUR(D306) -> 21 | I306: =IFERROR(VLOOKUP(tblOrders[[#This Row],[item_id]],Raw_Menu!$A$2:$D$33,3,FALSE),"Unknown") -> Asian
A307: 306 | B307: 130 | C307: 44928 | D307: 0.8853588 | E307: 129 | F307: =IFERROR(VLOOKUP(E307,Raw_Menu!$A$2:$D$33,4,FALSE),0) -> 15.5 | G307: =VALUE(F307) -> 15.5 | H307: =HOUR(D307) -> 21 | I307: =IFERROR(VLOOKUP(tblOrders[[#This Row],[item_id]],Raw_Menu!$A$2:$D$33,3,FALSE),"Unknown") -> Italian
A308: 307 | B308: 130 | C308: 44928 | D308: 0.8853588 | E308: 105 | F308: =IFERROR(VLOOKUP(E308,Raw_Menu!$A$2:$D$33,4,FALSE),0) -> 7 | G308: =VALUE(F308) -> 7 | H308: =HOUR(D308) -> 21 | I308: =IFERROR(VLOOKUP(tblOrders[[#This Row],[item_id]],Raw_Menu!$A$2:$D$33,3,FALSE),"Unknown") -> American
...
